Workbook

Sheet 使い方
A1: 見積依頼書ジェネレーター（Excel版）
A2: 物件の情報を入れると、業者に渡す見積依頼書（単価欄は空欄）が自動でできあがります。マクロは使っていません。
B4: やること | C4: 内容
A5: 1 | B5: 「入力」シートを開く | C5: STEP 1〜4 の黄色いセルに、お客様名・構造・階数・面積などを入れ、工事タイプを選びます。
A6: 2 | B6: 含める工事を確認する | C6: STEP 4 の表で、採用される工事が分かります。変えたいときだけ「手動で変更」に ○ か × を入れます。
A7: 3 | B7: 「見積書」シートで内訳を見る | C7: 選んだ内容に合わせて、工事ごとの内訳と数量が自動で並びます。
A8: 4 | B8: 業者に送る | C8: ファイルを別名で保存して送ります。業者は「見積書」の黄色い欄（単価・摘要）に入力します。
A9: 5 | B9: 返ってきた見積書を見る | C9: 業者が単価を入れると、金額・小計・合計が自動で計算されます。
A11: シートの役割
B12: 入力 | C12: 自分で入力・選択するシートです。ふだん触るのはここだけです。
B13: 見積書 | C13: 業者に渡すシートです。内訳は自動で並びます。単価と摘要だけ業者が入力します。
B14: マスタ | C14: 全項目の一覧です。項目の名前や単位を直したいときに使います。灰色のタブは、ふだん触らなくて大丈夫です。
A16: 気をつけること
B17: ・業者に送ったあとは、自社のファイルの「入力」シートを変えないでください。内訳の行の位置がずれて、業者の単価とずれます。
B18: ・数式を含まない見積書にしたいときは、「見積書」シートを全選択してコピーし、新しいブックに「値と元の書式設定」で貼り付けます。
B19: ・項目を足したいときは、マスタの小計行（行種別 S）の上に行を挿入し、K〜N列の数式を上の行からコピーしてください。
B20: ・「設定」シートは非表示です。工事タイプの中身を変えるときは、シートのタブを右クリック →「再表示」で開けます。
A22: 元のフォーマット（リフォーム・リノベーション工事見積書）の体裁に合わせています。

Sheet 入力
A1: 見積依頼書ジェネレーター
A2: STEP 1 → 5 の順に、黄色のセルへ入力・選択してください。（入力済みの内容は例です。上書きしてください）
A4: STEP 1 物件の基本情報
A5: お客様名 | D5: 例: 山田太郎 （「様邸」は自動で付きます）
A6: 工事名 | B6: リノベーション工事 | D6: 例: リノベーション工事
A7: 物件所在地
A8: 依頼元（自社名） | D8: 見積書の右上に表示されます
A9: 提出先（業者名） | D9: 「御中」は自動で付きます。業者ごとに変えて見積書を作ります
A10: 工事希望時期 | D10: 例: 2026年12月〜
A11: 見積提出期限 | D11: 日付を入力（例: 2026/11/30）
A12: 備考・特記事項 | D12: 搬入経路、工事時間の制限など、業者に伝えたいこと
A14: STEP 2 建物の条件を選ぶ
A15: ▼ が出るセルは、一覧から選びます。
A16: 構造 | B16: 木造 | D16: 木造以外では、木工事の木材項目が外れ、下地の項目に切り替わります
A17: 階数 | B17: 2階建て | D17: 選んだ階数に合わせて、2階・3階の項目だけが出ます
A18: 工事タイプ | B18: フルリノベーション | D18: 選ぶと、含める工事がSTEP 4の表で自動で決まります
A20: STEP 3 面積などの数値を入力
A21: 1階床面積 | B21: 63.6 | C21: ㎡ | D21: 解体・木工事・防蟻・養生清掃などの数量に使います
A22: 2階床面積 | B22: 33 | C22: ㎡ | D22: 平屋のときは使いません
A23: 3階床面積 | C23: ㎡ | D23: 3階建てのときだけ使います
A24: 屋根面積 | B24: 83 | C24: ㎡ | D24: 屋根板金工事の屋根葺き・防水シートに使います
A25: 外壁面積 | B25: 123.3 | C25: ㎡ | D25: 外壁の角波工事に使います
A26: 足場面積 | B26: 360 | C26: ㎡ | D26: 仮設足場・メッシュシートに使います（空欄なら外壁面積）
A27: トイレの数 | B27: 2 | C27: ヶ所 | D27: トイレ解体の数量に使います
A28: クロス貼りの延長 | B28: 670 | C28: m | D28: クロス貼りの数量に使います
A29: → 延床面積（自動計算） | B29: =IF('設定'!$K$4="","（未入力）",'設定'!$K$4&" ㎡（約 "&'設定'!$K$5&" 坪）") | D29: 選んだ階数の床面積の合計です
A31: STEP 4 含める工事を確認する
A32: 工事 | B32: タイプでの初期値 | C32: 手動で変更（○=含める / ×=外す） | D32: 結果（項目数）
A33: 解体工事 | B33: =IF(INDEX('設定'!$C$23:$F$23,'設定'!$K$7)=1,"含める","—") | D33: =IF('設定'!G23=1,"採用（"&COUNTIFS('マスタ'!$B$2:$B$246,1,'マスタ'!$A$2:$A$246,"I",'マスタ'!$L$2:$L$246,1)&"項目）","除外")
A34: 基礎工事 | B34: =IF(INDEX('設定'!$C$24:$F$24,'設定'!$K$7)=1,"含める","—") | D34: =IF('設定'!G24=1,"採用（"&COUNTIFS('マスタ'!$B$2:$B$246,2,'マスタ'!$A$2:$A$246,"I",'マスタ'!$L$2:$L$246,1)&"項目）","除外")
A35: 木工事 | B35: =IF(INDEX('設定'!$C$25:$F$25,'設定'!$K$7)=1,"含める","—") | D35: =IF('設定'!G25=1,"採用（"&COUNTIFS('マスタ'!$B$2:$B$246,3,'マスタ'!$A$2:$A$246,"I",'マスタ'!$L$2:$L$246,1)&"項目）","除外")
A36: 屋根板金工事 | B36: =IF(INDEX('設定'!$C$26:$F$26,'設定'!$K$7)=1,"含める","—") | D36: =IF('設定'!G26=1,"採用（"&COUNTIFS('マスタ'!$B$2:$B$246,4,'マスタ'!$A$2:$A$246,"I",'マスタ'!$L$2:$L$246,1)&"項目）","除外")
A37: 内外装工事 | B37: =IF(INDEX('設定'!$C$27:$F$27,'設定'!$K$7)=1,"含める","—") | D37: =IF('設定'!G27=1,"採用（"&COUNTIFS('マスタ'!$B$2:$B$246,5,'マスタ'!$A$2:$A$246,"I",'マスタ'!$L$2:$L$246,1)&"項目）","除外")
A38: 鋼製建具工事 | B38: =IF(INDEX('設定'!$C$28:$F$28,'設定'!$K$7)=1,"含める","—") | D38: =IF('設定'!G28=1,"採用（"&COUNTIFS('マスタ'!$B$2:$B$246,6,'マスタ'!$A$2:$A$246,"I",'マスタ'!$L$2:$L$246,1)&"項目）","除外")
A39: 塗装工事 | B39: =IF(INDEX('設定'!$C$29:$F$29,'設定'!$K$7)=1,"含める","—") | D39: =IF('設定'!G29=1,"採用（"&COUNTIFS('マスタ'!$B$2:$B$246,7,'マスタ'!$A$2:$A$246,"I",'マスタ'!$L$2:$L$246,1)&"項目）","除外")
A40: 電気設備工事 | B40: =IF(INDEX('設定'!$C$30:$F$30,'設定'!$K$7)=1,"含める","—") | D40: =IF('設定'!G30=1,"採用（"&COUNTIFS('マスタ'!$B$2:$B$246,8,'マスタ'!$A$2:$A$246,"I",'マスタ'!$L$2:$L$246,1)&"項目）","除外")
A41: 給排水設備工事 | B41: =IF(INDEX('設定'!$C$31:$F$31,'設定'!$K$7)=1,"含める","—") | D41: =IF('設定'!G31=1,"採用（"&COUNTIFS('マスタ'!$B$2:$B$246,9,'マスタ'!$A$2:$A$246,"I",'マスタ'!$L$2:$L$246,1)&"項目）","除外")
A42: 住宅設備工事 | B42: =IF(INDEX('設定'!$C$32:$F$32,'設定'!$K$7)=1,"含める","—") | D42: =IF('設定'!G32=1,"採用（"&COUNTIFS('マスタ'!$B$2:$B$246,10,'マスタ'!$A$2:$A$246,"I",'マスタ'!$L$2:$L$246,1)&"項目）","除外")
A43: 仮設工事 | B43: =IF(INDEX('設定'!$C$33:$F$33,'設定'!$K$7)=1,"含める","—") | D43: =IF('設定'!G33=1,"採用（"&COUNTIFS('マスタ'!$B$2:$B$246,11,'マスタ'!$A$2:$A$246,"I",'マスタ'!$L$2:$L$246,1)&"項目）","除外")
A44: 諸経費 | B44: =IF(INDEX('設定'!$C$34:$F$34,'設定'!$K$7)=1,"含める","—") | D44: =IF('設定'!G34=1,"採用（"&COUNTIFS('マスタ'!$B$2:$B$246,12,'マスタ'!$A$2:$A$246,"I",'マスタ'!$L$2:$L$246,1)&"項目）","除外")
...

Sheet 見積書
B1: =IF('入力'!B5="","お名前",'入力'!B5)&" 様邸"&'入力'!B6&" 見積書" | G1: ※ 黄色の欄（単価・摘要）をご記入ください
B2: =IF('入力'!B9="","",'入力'!B9&" 御中") | G2: ='入力'!B8&""
A3: No. | B3: 名 称 | C3: 仕 様 | D3: 数量 | F3: 単位 | G3: 単 価 | I3: 金 額 | K3: 摘 要
A4: （内 訳 明 細）
A5: =IF(N5="","",1) | B5: =IF(N5="","",INDEX('設定'!$B$23:$B$34,N5)) | D5: =IF(N5="","",1) | F5: =IF(N5="","","式") | I5: =IF(N5="","",SUMIFS(I$24:I$274,N$24:N$274,N5,M$24:M$274,"S")) | N5: =IFERROR(MATCH(1,'設定'!$H$23:$H$34,0),"")
A6: =IF(N6="","",2) | B6: =IF(N6="","",INDEX('設定'!$B$23:$B$34,N6)) | D6: =IF(N6="","",1) | F6: =IF(N6="","","式") | I6: =IF(N6="","",SUMIFS(I$24:I$274,N$24:N$274,N6,M$24:M$274,"S")) | N6: =IFERROR(MATCH(2,'設定'!$H$23:$H$34,0),"")
A7: =IF(N7="","",3) | B7: =IF(N7="","",INDEX('設定'!$B$23:$B$34,N7)) | D7: =IF(N7="","",1) | F7: =IF(N7="","","式") | I7: =IF(N7="","",SUMIFS(I$24:I$274,N$24:N$274,N7,M$24:M$274,"S")) | N7: =IFERROR(MATCH(3,'設定'!$H$23:$H$34,0),"")
A8: =IF(N8="","",4) | B8: =IF(N8="","",INDEX('設定'!$B$23:$B$34,N8)) | D8: =IF(N8="","",1) | F8: =IF(N8="","","式") | I8: =IF(N8="","",SUMIFS(I$24:I$274,N$24:N$274,N8,M$24:M$274,"S")) | N8: =IFERROR(MATCH(4,'設定'!$H$23:$H$34,0),"")
A9: =IF(N9="","",5) | B9: =IF(N9="","",INDEX('設定'!$B$23:$B$34,N9)) | D9: =IF(N9="","",1) | F9: =IF(N9="","","式") | I9: =IF(N9="","",SUMIFS(I$24:I$274,N$24:N$274,N9,M$24:M$274,"S")) | N9: =IFERROR(MATCH(5,'設定'!$H$23:$H$34,0),"")
A10: =IF(N10="","",6) | B10: =IF(N10="","",INDEX('設定'!$B$23:$B$34,N10)) | D10: =IF(N10="","",1) | F10: =IF(N10="","","式") | I10: =IF(N10="","",SUMIFS(I$24:I$274,N$24:N$274,N10,M$24:M$274,"S")) | N10: =IFERROR(MATCH(6,'設定'!$H$23:$H$34,0),"")
A11: =IF(N11="","",7) | B11: =IF(N11="","",INDEX('設定'!$B$23:$B$34,N11)) | D11: =IF(N11="","",1) | F11: =IF(N11="","","式") | I11: =IF(N11="","",SUMIFS(I$24:I$274,N$24:N$274,N11,M$24:M$274,"S")) | N11: =IFERROR(MATCH(7,'設定'!$H$23:$H$34,0),"")
A12: =IF(N12="","",8) | B12: =IF(N12="","",INDEX('設定'!$B$23:$B$34,N12)) | D12: =IF(N12="","",1) | F12: =IF(N12="","","式") | I12: =IF(N12="","",SUMIFS(I$24:I$274,N$24:N$274,N12,M$24:M$274,"S")) | N12: =IFERROR(MATCH(8,'設定'!$H$23:$H$34,0),"")
A13: =IF(N13="","",9) | B13: =IF(N13="","",INDEX('設定'!$B$23:$B$34,N13)) | D13: =IF(N13="","",1) | F13: =IF(N13="","","式") | I13: =IF(N13="","",SUMIFS(I$24:I$274,N$24:N$274,N13,M$24:M$274,"S")) | N13: =IFERROR(MATCH(9,'設定'!$H$23:$H$34,0),"")
A14: =IF(N14="","",10) | B14: =IF(N14="","",INDEX('設定'!$B$23:$B$34,N14)) | D14: =IF(N14="","",1) | F14: =IF(N14="","","式") | I14: =IF(N14="","",SUMIFS(I$24:I$274,N$24:N$274,N14,M$24:M$274,"S")) | N14: =IFERROR(MATCH(10,'設定'!$H$23:$H$34,0),"")
A15: =IF(N15="","",11) | B15: =IF(N15="","",INDEX('設定'!$B$23:$B$34,N15)) | D15: =IF(N15="","",1) | F15: =IF(N15="","","式") | I15: =IF(N15="","",SUMIFS(I$24:I$274,N$24:N$274,N15,M$24:M$274,"S")) | N15: =IFERROR(MATCH(11,'設定'!$H$23:$H$34,0),"")
A16: =IF(N16="","",12) | B16: =IF(N16="","",INDEX('設定'!$B$23:$B$34,N16)) | D16: =IF(N16="","",1) | F16: =IF(N16="","","式") | I16: =IF(N16="","",SUMIFS(I$24:I$274,N$24:N$274,N16,M$24:M$274,"S")) | N16: =IFERROR(MATCH(12,'設定'!$H$23:$H$34,0),"")
B18: 調整費
B20: 合 計 | I20: =SUM(I5:I16)+N(I18)
B21: ="構造: "&'入力'!B16&" / "&'入力'!B17&IF('設定'!$K$4="","",", 延床 "&'設定'!$K$4&"㎡（"&'設定'!$K$5&"坪）")&IF('入力'!B11="","", " / 提出期限 "&TEXT('入力'!B11,"yyyy/m/d"))
B22: =IF('入力'!B12="","","備考: "&'入力'!B12)
A23: （内 訳 明 細）
A24: =IF(M24="T",INDEX('設定'!$H$23:$H$34,N24),"") | B24: =IF(OR(L24="",M24="B"),"",INDEX('マスタ'!$C$2:$C$246,L24)) | C24: =IF(M24="I",INDEX('マスタ'!$D$2:$D$246,L24)&"","") | D24: =IF(M24="I",INDEX('マスタ'!$M$2:$M$246,L24),"") | F24: =IF(M24="I",INDEX('マスタ'!$F$2:$F$246,L24)&"","") | I24: =IF(AND(M24="I",G24<>"",D24<>""),ROUND(D24*G24,0),"") | L24: =IFERROR(MATCH(1,'マスタ'!$N$2:$N$246,0),"") | M24: =IF(L24="","",INDEX('マスタ'!$A$2:$A$246,L24)) | N24: =IF(L24="","",INDEX('マスタ'!$B$2:$B$246,L24))
A25: =IF(M25="T",INDEX('設定'!$H$23:$H$34,N25),"") | B25: =IF(OR(L25="",M25="B"),"",INDEX('マスタ'!$C$2:$C$246,L25)) | C25: =IF(M25="I",INDEX('マスタ'!$D$2:$D$246,L25)&"","") | D25: =IF(M25="I",INDEX('マスタ'!$M$2:$M$246,L25),"") | F25: =IF(M25="I",INDEX('マスタ'!$F$2:$F$246,L25)&"","") | I25: =IF(M25="I",IF(OR(G25="",D25=""),"",ROUND(D25*G25,0)),IF(M25="S",SUMIFS(I$24:I24,N$24:N24,N25,M$24:M24,"I"),"")) | L25: =IFERROR(MATCH(2,'マスタ'!$N$2:$N$246,0),"") | M25: =IF(L25="","",INDEX('マスタ'!$A$2:$A$246,L25)) | N25: =IF(L25="","",INDEX('マスタ'!$B$2:$B$246,L25))
A26: =IF(M26="T",INDEX('設定'!$H$23:$H$34,N26),"") | B26: =IF(OR(L26="",M26="B"),"",INDEX('マスタ'!$C$2:$C$246,L26)) | C26: =IF(M26="I",INDEX('マスタ'!$D$2:$D$246,L26)&"","") | D26: =IF(M26="I",INDEX('マスタ'!$M$2:$M$246,L26),"") | F26: =IF(M26="I",INDEX('マスタ'!$F$2:$F$246,L26)&"","") | I26: =IF(M26="I",IF(OR(G26="",D26=""),"",ROUND(D26*G26,0)),IF(M26="S",SUMIFS(I$24:I25,N$24:N25,N26,M$24:M25,"I"),"")) | L26: =IFERROR(MATCH(3,'マスタ'!$N$2:$N$246,0),"") | M26: =IF(L26="","",INDEX('マスタ'!$A$2:$A$246,L26)) | N26: =IF(L26="","",INDEX('マスタ'!$B$2:$B$246,L26))
A27: =IF(M27="T",INDEX('設定'!$H$23:$H$34,N27),"") | B27: =IF(OR(L27="",M27="B"),"",INDEX('マスタ'!$C$2:$C$246,L27)) | C27: =IF(M27="I",INDEX('マスタ'!$D$2:$D$246,L27)&"","") | D27: =IF(M27="I",INDEX('マスタ'!$M$2:$M$246,L27),"") | F27: =IF(M27="I",INDEX('マスタ'!$F$2:$F$246,L27)&"","") | I27: =IF(M27="I",IF(OR(G27="",D27=""),"",ROUND(D27*G27,0)),IF(M27="S",SUMIFS(I$24:I26,N$24:N26,N27,M$24:M26,"I"),"")) | L27: =IFERROR(MATCH(4,'マスタ'!$N$2:$N$246,0),"") | M27: =IF(L27="","",INDEX('マスタ'!$A$2:$A$246,L27)) | N27: =IF(L27="","",INDEX('マスタ'!$B$2:$B$246,L27))
A28: =IF(M28="T",INDEX('設定'!$H$23:$H$34,N28),"") | B28: =IF(OR(L28="",M28="B"),"",INDEX('マスタ'!$C$2:$C$246,L28)) | C28: =IF(M28="I",INDEX('マスタ'!$D$2:$D$246,L28)&"","") | D28: =IF(M28="I",INDEX('マスタ'!$M$2:$M$246,L28),"") | F28: =IF(M28="I",INDEX('マスタ'!$F$2:$F$246,L28)&"","") | I28: =IF(M28="I",IF(OR(G28="",D28=""),"",ROUND(D28*G28,0)),IF(M28="S",SUMIFS(I$24:I27,N$24:N27,N28,M$24:M27,"I"),"")) | L28: =IFERROR(MATCH(5,'マスタ'!$N$2:$N$246,0),"") | M28: =IF(L28="","",INDEX('マスタ'!$A$2:$A$246,L28)) | N28: =IF(L28="","",INDEX('マスタ'!$B$2:$B$246,L28))
A29: =IF(M29="T",INDEX('設定'!$H$23:$H$34,N29),"") | B29: =IF(OR(L29="",M29="B"),"",INDEX('マスタ'!$C$2:$C$246,L29)) | C29: =IF(M29="I",INDEX('マスタ'!$D$2:$D$246,L29)&"","") | D29: =IF(M29="I",INDEX('マスタ'!$M$2:$M$246,L29),"") | F29: =IF(M29="I",INDEX('マスタ'!$F$2:$F$246,L29)&"","") | I29: =IF(M29="I",IF(OR(G29="",D29=""),"",ROUND(D29*G29,0)),IF(M29="S",SUMIFS(I$24:I28,N$24:N28,N29,M$24:M28,"I"),"")) | L29: =IFERROR(MATCH(6,'マスタ'!$N$2:$N$246,0),"") | M29: =IF(L29="","",INDEX('マスタ'!$A$2:$A$246,L29)) | N29: =IF(L29="","",INDEX('マスタ'!$B$2:$B$246,L29))
A30: =IF(M30="T",INDEX('設定'!$H$23:$H$34,N30),"") | B30: =IF(OR(L30="",M30="B"),"",INDEX('マスタ'!$C$2:$C$246,L30)) | C30: =IF(M30="I",INDEX('マスタ'!$D$2:$D$246,L30)&"","") | D30: =IF(M30="I",INDEX('マスタ'!$M$2:$M$246,L30),"") | F30: =IF(M30="I",INDEX('マスタ'!$F$2:$F$246,L30)&"","") | I30: =IF(M30="I",IF(OR(G30="",D30=""),"",ROUND(D30*G30,0)),IF(M30="S",SUMIFS(I$24:I29,N$24:N29,N30,M$24:M29,"I"),"")) | L30: =IFERROR(MATCH(7,'マスタ'!$N$2:$N$246,0),"") | M30: =IF(L30="","",INDEX('マスタ'!$A$2:$A$246,L30)) | N30: =IF(L30="","",INDEX('マスタ'!$B$2:$B$246,L30))
A31: =IF(M31="T",INDEX('設定'!$H$23:$H$34,N31),"") | B31: =IF(OR(L31="",M31="B"),"",INDEX('マスタ'!$C$2:$C$246,L31)) | C31: =IF(M31="I",INDEX('マスタ'!$D$2:$D$246,L31)&"","") | D31: =IF(M31="I",INDEX('マスタ'!$M$2:$M$246,L31),"") | F31: =IF(M31="I",INDEX('マスタ'!$F$2:$F$246,L31)&"","") | I31: =IF(M31="I",IF(OR(G31="",D31=""),"",ROUND(D31*G31,0)),IF(M31="S",SUMIFS(I$24:I30,N$24:N30,N31,M$24:M30,"I"),"")) | L31: =IFERROR(MATCH(8,'マスタ'!$N$2:$N$246,0),"") | M31: =IF(L31="","",INDEX('マスタ'!$A$2:$A$246,L31)) | N31: =IF(L31="","",INDEX('マスタ'!$B$2:$B$246,L31))
A32: =IF(M32="T",INDEX('設定'!$H$23:$H$34,N32),"") | B32: =IF(OR(L32="",M32="B"),"",INDEX('マスタ'!$C$2:$C$246,L32)) | C32: =IF(M32="I",INDEX('マスタ'!$D$2:$D$246,L32)&"","") | D32: =IF(M32="I",INDEX('マスタ'!$M$2:$M$246,L32),"") | F32: =IF(M32="I",INDEX('マスタ'!$F$2:$F$246,L32)&"","") | I32: =IF(M32="I",IF(OR(G32="",D32=""),"",ROUND(D32*G32,0)),IF(M32="S",SUMIFS(I$24:I31,N$24:N31,N32,M$24:M31,"I"),"")) | L32: =IFERROR(MATCH(9,'マスタ'!$N$2:$N$246,0),"") | M32: =IF(L32="","",INDEX('マスタ'!$A$2:$A$246,L32)) | N32: =IF(L32="","",INDEX('マスタ'!$B$2:$B$246,L32))
A33: =IF(M33="T",INDEX('設定'!$H$23:$H$34,N33),"") | B33: =IF(OR(L33="",M33="B"),"",INDEX('マスタ'!$C$2:$C$246,L33)) | C33: =IF(M33="I",INDEX('マスタ'!$D$2:$D$246,L33)&"","") | D33: =IF(M33="I",INDEX('マスタ'!$M$2:$M$246,L33),"") | F33: =IF(M33="I",INDEX('マスタ'!$F$2:$F$246,L33)&"","") | I33: =IF(M33="I",IF(OR(G33="",D33=""),"",ROUND(D33*G33,0)),IF(M33="S",SUMIFS(I$24:I32,N$24:N32,N33,M$24:M32,"I"),"")) | L33: =IFERROR(MATCH(10,'マスタ'!$N$2:$N$246,0),"") | M33: =IF(L33="","",INDEX('マスタ'!$A$2:$A$246,L33)) | N33: =IF(L33="","",INDEX('マスタ'!$B$2:$B$246,L33))
A34: =IF(M34="T",INDEX('設定'!$H$23:$H$34,N34),"") | B34: =IF(OR(L34="",M34="B"),"",INDEX('マスタ'!$C$2:$C$246,L34)) | C34: =IF(M34="I",INDEX('マスタ'!$D$2:$D$246,L34)&"","") | D34: =IF(M34="I",INDEX('マスタ'!$M$2:$M$246,L34),"") | F34: =IF(M34="I",INDEX('マスタ'!$F$2:$F$246,L34)&"","") | I34: =IF(M34="I",IF(OR(G34="",D34=""),"",ROUND(D34*G34,0)),IF(M34="S",SUMIFS(I$24:I33,N$24:N33,N34,M$24:M33,"I"),"")) | L34: =IFERROR(MATCH(11,'マスタ'!$N$2:$N$246,0),"") | M34: =IF(L34="","",INDEX('マスタ'!$A$2:$A$246,L34)) | N34: =IF(L34="","",INDEX('マスタ'!$B$2:$B$246,L34))
A35: =IF(M35="T",INDEX('設定'!$H$23:$H$34,N35),"") | B35: =IF(OR(L35="",M35="B"),"",INDEX('マスタ'!$C$2:$C$246,L35)) | C35: =IF(M35="I",INDEX('マスタ'!$D$2:$D$246,L35)&"","") | D35: =IF(M35="I",INDEX('マスタ'!$M$2:$M$246,L35),"") | F35: =IF(M35="I",INDEX('マスタ'!$F$2:$F$246,L35)&"","") | I35: =IF(M35="I",IF(OR(G35="",D35=""),"",ROUND(D35*G35,0)),IF(M35="S",SUMIFS(I$24:I34,N$24:N34,N35,M$24:M34,"I"),"")) | L35: =IFERROR(MATCH(12,'マスタ'!$N$2:$N$246,0),"") | M35: =IF(L35="","",INDEX('マスタ'!$A$2:$A$246,L35)) | N35: =IF(L35="","",INDEX('マスタ'!$B$2:$B$246,L35))
A36: =IF(M36="T",INDEX('設定'!$H$23:$H$34,N36),"") | B36: =IF(OR(L36="",M36="B"),"",INDEX('マスタ'!$C$2:$C$246,L36)) | C36: =IF(M36="I",INDEX('マスタ'!$D$2:$D$246,L36)&"","") | D36: =IF(M36="I",INDEX('マスタ'!$M$2:$M$246,L36),"") | F36: =IF(M36="I",INDEX('マスタ'!$F$2:$F$246,L36)&"","") | I36: =IF(M36="I",IF(OR(G36="",D36=""),"",ROUND(D36*G36,0)),IF(M36="S",SUMIFS(I$24:I35,N$24:N35,N36,M$24:M35,"I"),"")) | L36: =IFERROR(MATCH(13,'マスタ'!$N$2:$N$246,0),"") | M36: =IF(L36="","",INDEX('マスタ'!$A$2:$A$246,L36)) | N36: =IF(L36="","",INDEX('マスタ'!$B$2:$B$246,L36))
A37: =IF(M37="T",INDEX('設定'!$H$23:$H$34,N37),"") | B37: =IF(OR(L37="",M37="B"),"",INDEX('マスタ'!$C$2:$C$246,L37)) | C37: =IF(M37="I",INDEX('マスタ'!$D$2:$D$246,L37)&"","") | D37: =IF(M37="I",INDEX('マスタ'!$M$2:$M$246,L37),"") | F37: =IF(M37="I",INDEX('マスタ'!$F$2:$F$246,L37)&"","") | I37: =IF(M37="I",IF(OR(G37="",D37=""),"",ROUND(D37*G37,0)),IF(M37="S",SUMIFS(I$24:I36,N$24:N36,N37,M$24:M36,"I"),"")) | L37: =IFERROR(MATCH(14,'マスタ'!$N$2:$N$246,0),"") | M37: =IF(L37="","",INDEX('マスタ'!$A$2:$A$246,L37)) | N37: =IF(L37="","",INDEX('マスタ'!$B$2:$B$246,L37))
A38: =IF(M38="T",INDEX('設定'!$H$23:$H$34,N38),"") | B38: =IF(OR(L38="",M38="B"),"",INDEX('マスタ'!$C$2:$C$246,L38)) | C38: =IF(M38="I",INDEX('マスタ'!$D$2:$D$246,L38)&"","") | D38: =IF(M38="I",INDEX('マスタ'!$M$2:$M$246,L38),"") | F38: =IF(M38="I",INDEX('マスタ'!$F$2:$F$246,L38)&"","") | I38: =IF(M38="I",IF(OR(G38="",D38=""),"",ROUND(D38*G38,0)),IF(M38="S",SUMIFS(I$24:I37,N$24:N37,N38,M$24:M37,"I"),"")) | L38: =IFERROR(MATCH(15,'マスタ'!$N$2:$N$246,0),"") | M38: =IF(L38="","",INDEX('マスタ'!$A$2:$A$246,L38)) | N38: =IF(L38="","",INDEX('マスタ'!$B$2:$B$246,L38))
A39: =IF(M39="T",INDEX('設定'!$H$23:$H$34,N39),"") | B39: =IF(OR(L39="",M39="B"),"",INDEX('マスタ'!$C$2:$C$246,L39)) | C39: =IF(M39="I",INDEX('マスタ'!$D$2:$D$246,L39)&"","") | D39: =IF(M39="I",INDEX('マスタ'!$M$2:$M$246,L39),"") | F39: =IF(M39="I",INDEX('マスタ'!$F$2:$F$246,L39)&"","") | I39: =IF(M39="I",IF(OR(G39="",D39=""),"",ROUND(D39*G39,0)),IF(M39="S",SUMIFS(I$24:I38,N$24:N38,N39,M$24:M38,"I"),"")) | L39: =IFERROR(MATCH(16,'マスタ'!$N$2:$N$246,0),"") | M39: =IF(L39="","",INDEX('マスタ'!$A$2:$A$246,L39)) | N39: =IF(L39="","",INDEX('マスタ'!$B$2:$B$246,L39))
A40: =IF(M40="T",INDEX('設定'!$H$23:$H$34,N40),"") | B40: =IF(OR(L40="",M40="B"),"",INDEX('マスタ'!$C$2:$C$246,L40)) | C40: =IF(M40="I",INDEX('マスタ'!$D$2:$D$246,L40)&"","") | D40: =IF(M40="I",INDEX('マスタ'!$M$2:$M$246,L40),"") | F40: =IF(M40="I",INDEX('マスタ'!$F$2:$F$246,L40)&"","") | I40: =IF(M40="I",IF(OR(G40="",D40=""),"",ROUND(D40*G40,0)),IF(M40="S",SUMIFS(I$24:I39,N$24:N39,N40,M$24:M39,"I"),"")) | L40: =IFERROR(MATCH(17,'マスタ'!$N$2:$N$246,0),"") | M40: =IF(L40="","",INDEX('マスタ'!$A$2:$A$246,L40)) | N40: =IF(L40="","",INDEX('マスタ'!$B$2:$B$246,L40))
A41: =IF(M41="T",INDEX('設定'!$H$23:$H$34,N41),"") | B41: =IF(OR(L41="",M41="B"),"",INDEX('マスタ'!$C$2:$C$246,L41)) | C41: =IF(M41="I",INDEX('マスタ'!$D$2:$D$246,L41)&"","") | D41: =IF(M41="I",INDEX('マスタ'!$M$2:$M$246,L41),"") | F41: =IF(M41="I",INDEX('マスタ'!$F$2:$F$246,L41)&"","") | I41: =IF(M41="I",IF(OR(G41="",D41=""),"",ROUND(D41*G41,0)),IF(M41="S",SUMIFS(I$24:I40,N$24:N40,N41,M$24:M40,"I"),"")) | L41: =IFERROR(MATCH(18,'マスタ'!$N$2:$N$246,0),"") | M41: =IF(L41="","",INDEX('マスタ'!$A$2:$A$246,L41)) | N41: =IF(L41="","",INDEX('マスタ'!$B$2:$B$246,L41))
A42: =IF(M42="T",INDEX('設定'!$H$23:$H$34,N42),"") | B42: =IF(OR(L42="",M42="B"),"",INDEX('マスタ'!$C$2:$C$246,L42)) | C42: =IF(M42="I",INDEX('マスタ'!$D$2:$D$246,L42)&"","") | D42: =IF(M42="I",INDEX('マスタ'!$M$2:$M$246,L42),"") | F42: =IF(M42="I",INDEX('マスタ'!$F$2:$F$246,L42)&"","") | I42: =IF(M42="I",IF(OR(G42="",D42=""),"",ROUND(D42*G42,0)),IF(M42="S",SUMIFS(I$24:I41,N$24:N41,N42,M$24:M41,"I"),"")) | L42: =IFERROR(MATCH(19,'マスタ'!$N$2:$N$246,0),"") | M42: =IF(L42="","",INDEX('マスタ'!$A$2:$A$246,L42)) | N42: =IF(L42="","",INDEX('マスタ'!$B$2:$B$246,L42))
...

Sheet マスタ
A1: 行種別 | B1: 工事ID | C1: 名称 | D1: 仕様 | E1: 既定数量 | F1: 単位 | G1: 基準キー | H1: 係数 | I1: 最低階数 | J1: 構造限定 | K1: 採用工事 | L1: 表示 | M1: 数量 | N1: 連番
A2: T | B2: 1 | C2: 解体工事 | K2: =INDEX('設定'!$G$23:$G$34,B2) | L2: =IF(K2<>1,0,IF(OR(A2="T",A2="S",A2="B"),1,IF(AND(OR(I2="",I2<='設定'!$K$2),OR(J2="",ISNUMBER(SEARCH('設定'!$K$3,J2)))),1,0))) | M2: =IF(A2<>"I","",IF(G2="",E2,IFERROR(IF(VLOOKUP(G2,'設定'!$A$9:$B$18,2,FALSE)="",E2,ROUND(VLOOKUP(G2,'設定'!$A$9:$B$18,2,FALSE)*H2,2)),E2))) | N2: =IF(L2=1,COUNTIF(L$2:L2,1),"")
A3: I | B3: 1 | C3: 1階スケルトン解体処分 | E3: 63.6 | F3: ㎡ | G3: floor1_area | H3: 1 | K3: =INDEX('設定'!$G$23:$G$34,B3) | L3: =IF(K3<>1,0,IF(OR(A3="T",A3="S",A3="B"),1,IF(AND(OR(I3="",I3<='設定'!$K$2),OR(J3="",ISNUMBER(SEARCH('設定'!$K$3,J3)))),1,0))) | M3: =IF(A3<>"I","",IF(G3="",E3,IFERROR(IF(VLOOKUP(G3,'設定'!$A$9:$B$18,2,FALSE)="",E3,ROUND(VLOOKUP(G3,'設定'!$A$9:$B$18,2,FALSE)*H3,2)),E3))) | N3: =IF(L3=1,COUNTIF(L$2:L3,1),"")
A4: I | B4: 1 | C4: 2階スケルトン解体処分 | E4: 33 | F4: ㎡ | G4: floor2_area | H4: 1 | I4: 2 | K4: =INDEX('設定'!$G$23:$G$34,B4) | L4: =IF(K4<>1,0,IF(OR(A4="T",A4="S",A4="B"),1,IF(AND(OR(I4="",I4<='設定'!$K$2),OR(J4="",ISNUMBER(SEARCH('設定'!$K$3,J4)))),1,0))) | M4: =IF(A4<>"I","",IF(G4="",E4,IFERROR(IF(VLOOKUP(G4,'設定'!$A$9:$B$18,2,FALSE)="",E4,ROUND(VLOOKUP(G4,'設定'!$A$9:$B$18,2,FALSE)*H4,2)),E4))) | N4: =IF(L4=1,COUNTIF(L$2:L4,1),"")
A5: I | B5: 1 | C5: 3階スケルトン解体処分 | E5: 1 | F5: ㎡ | G5: floor3_area | H5: 1 | I5: 3 | K5: =INDEX('設定'!$G$23:$G$34,B5) | L5: =IF(K5<>1,0,IF(OR(A5="T",A5="S",A5="B"),1,IF(AND(OR(I5="",I5<='設定'!$K$2),OR(J5="",ISNUMBER(SEARCH('設定'!$K$3,J5)))),1,0))) | M5: =IF(A5<>"I","",IF(G5="",E5,IFERROR(IF(VLOOKUP(G5,'設定'!$A$9:$B$18,2,FALSE)="",E5,ROUND(VLOOKUP(G5,'設定'!$A$9:$B$18,2,FALSE)*H5,2)),E5))) | N5: =IF(L5=1,COUNTIF(L$2:L5,1),"")
A6: I | B6: 1 | C6: 浴室解体処分 | E6: 1 | F6: 式 | K6: =INDEX('設定'!$G$23:$G$34,B6) | L6: =IF(K6<>1,0,IF(OR(A6="T",A6="S",A6="B"),1,IF(AND(OR(I6="",I6<='設定'!$K$2),OR(J6="",ISNUMBER(SEARCH('設定'!$K$3,J6)))),1,0))) | M6: =IF(A6<>"I","",IF(G6="",E6,IFERROR(IF(VLOOKUP(G6,'設定'!$A$9:$B$18,2,FALSE)="",E6,ROUND(VLOOKUP(G6,'設定'!$A$9:$B$18,2,FALSE)*H6,2)),E6))) | N6: =IF(L6=1,COUNTIF(L$2:L6,1),"")
A7: I | B7: 1 | C7: 1階和室、脱衣室等解体処分 | E7: 26 | F7: ㎡ | K7: =INDEX('設定'!$G$23:$G$34,B7) | L7: =IF(K7<>1,0,IF(OR(A7="T",A7="S",A7="B"),1,IF(AND(OR(I7="",I7<='設定'!$K$2),OR(J7="",ISNUMBER(SEARCH('設定'!$K$3,J7)))),1,0))) | M7: =IF(A7<>"I","",IF(G7="",E7,IFERROR(IF(VLOOKUP(G7,'設定'!$A$9:$B$18,2,FALSE)="",E7,ROUND(VLOOKUP(G7,'設定'!$A$9:$B$18,2,FALSE)*H7,2)),E7))) | N7: =IF(L7=1,COUNTIF(L$2:L7,1),"")
A8: I | B8: 1 | C8: トイレ解体処分 | E8: 2 | F8: ヶ処 | G8: toilet_count | H8: 1 | K8: =INDEX('設定'!$G$23:$G$34,B8) | L8: =IF(K8<>1,0,IF(OR(A8="T",A8="S",A8="B"),1,IF(AND(OR(I8="",I8<='設定'!$K$2),OR(J8="",ISNUMBER(SEARCH('設定'!$K$3,J8)))),1,0))) | M8: =IF(A8<>"I","",IF(G8="",E8,IFERROR(IF(VLOOKUP(G8,'設定'!$A$9:$B$18,2,FALSE)="",E8,ROUND(VLOOKUP(G8,'設定'!$A$9:$B$18,2,FALSE)*H8,2)),E8))) | N8: =IF(L8=1,COUNTIF(L$2:L8,1),"")
A9: I | B9: 1 | C9: 物置屋根解体処分 | E9: 1 | F9: 式 | K9: =INDEX('設定'!$G$23:$G$34,B9) | L9: =IF(K9<>1,0,IF(OR(A9="T",A9="S",A9="B"),1,IF(AND(OR(I9="",I9<='設定'!$K$2),OR(J9="",ISNUMBER(SEARCH('設定'!$K$3,J9)))),1,0))) | M9: =IF(A9<>"I","",IF(G9="",E9,IFERROR(IF(VLOOKUP(G9,'設定'!$A$9:$B$18,2,FALSE)="",E9,ROUND(VLOOKUP(G9,'設定'!$A$9:$B$18,2,FALSE)*H9,2)),E9))) | N9: =IF(L9=1,COUNTIF(L$2:L9,1),"")
A10: I | B10: 1 | C10: 小屋根解体処分 | D10: アルミバルコニー共 | E10: 1 | F10: 式 | K10: =INDEX('設定'!$G$23:$G$34,B10) | L10: =IF(K10<>1,0,IF(OR(A10="T",A10="S",A10="B"),1,IF(AND(OR(I10="",I10<='設定'!$K$2),OR(J10="",ISNUMBER(SEARCH('設定'!$K$3,J10)))),1,0))) | M10: =IF(A10<>"I","",IF(G10="",E10,IFERROR(IF(VLOOKUP(G10,'設定'!$A$9:$B$18,2,FALSE)="",E10,ROUND(VLOOKUP(G10,'設定'!$A$9:$B$18,2,FALSE)*H10,2)),E10))) | N10: =IF(L10=1,COUNTIF(L$2:L10,1),"")
A11: I | B11: 1 | C11: コンクリート斫り・コア抜き | E11: 1 | F11: 式 | J11: rc | K11: =INDEX('設定'!$G$23:$G$34,B11) | L11: =IF(K11<>1,0,IF(OR(A11="T",A11="S",A11="B"),1,IF(AND(OR(I11="",I11<='設定'!$K$2),OR(J11="",ISNUMBER(SEARCH('設定'!$K$3,J11)))),1,0))) | M11: =IF(A11<>"I","",IF(G11="",E11,IFERROR(IF(VLOOKUP(G11,'設定'!$A$9:$B$18,2,FALSE)="",E11,ROUND(VLOOKUP(G11,'設定'!$A$9:$B$18,2,FALSE)*H11,2)),E11))) | N11: =IF(L11=1,COUNTIF(L$2:L11,1),"")
A12: S | B12: 1 | C12: 小 計 | K12: =INDEX('設定'!$G$23:$G$34,B12) | L12: =IF(K12<>1,0,IF(OR(A12="T",A12="S",A12="B"),1,IF(AND(OR(I12="",I12<='設定'!$K$2),OR(J12="",ISNUMBER(SEARCH('設定'!$K$3,J12)))),1,0))) | M12: =IF(A12<>"I","",IF(G12="",E12,IFERROR(IF(VLOOKUP(G12,'設定'!$A$9:$B$18,2,FALSE)="",E12,ROUND(VLOOKUP(G12,'設定'!$A$9:$B$18,2,FALSE)*H12,2)),E12))) | N12: =IF(L12=1,COUNTIF(L$2:L12,1),"")
A13: B | B13: 1 | K13: =INDEX('設定'!$G$23:$G$34,B13) | L13: =IF(K13<>1,0,IF(OR(A13="T",A13="S",A13="B"),1,IF(AND(OR(I13="",I13<='設定'!$K$2),OR(J13="",ISNUMBER(SEARCH('設定'!$K$3,J13)))),1,0))) | M13: =IF(A13<>"I","",IF(G13="",E13,IFERROR(IF(VLOOKUP(G13,'設定'!$A$9:$B$18,2,FALSE)="",E13,ROUND(VLOOKUP(G13,'設定'!$A$9:$B$18,2,FALSE)*H13,2)),E13))) | N13: =IF(L13=1,COUNTIF(L$2:L13,1),"")
A14: T | B14: 2 | C14: 基礎工事 | K14: =INDEX('設定'!$G$23:$G$34,B14) | L14: =IF(K14<>1,0,IF(OR(A14="T",A14="S",A14="B"),1,IF(AND(OR(I14="",I14<='設定'!$K$2),OR(J14="",ISNUMBER(SEARCH('設定'!$K$3,J14)))),1,0))) | M14: =IF(A14<>"I","",IF(G14="",E14,IFERROR(IF(VLOOKUP(G14,'設定'!$A$9:$B$18,2,FALSE)="",E14,ROUND(VLOOKUP(G14,'設定'!$A$9:$B$18,2,FALSE)*H14,2)),E14))) | N14: =IF(L14=1,COUNTIF(L$2:L14,1),"")
A15: I | B15: 2 | C15: 玄関土間・ポーチ | D15: 300角磁器質タイル or 洗出し仕上げ | E15: 6.6 | F15: ㎡ | K15: =INDEX('設定'!$G$23:$G$34,B15) | L15: =IF(K15<>1,0,IF(OR(A15="T",A15="S",A15="B"),1,IF(AND(OR(I15="",I15<='設定'!$K$2),OR(J15="",ISNUMBER(SEARCH('設定'!$K$3,J15)))),1,0))) | M15: =IF(A15<>"I","",IF(G15="",E15,IFERROR(IF(VLOOKUP(G15,'設定'!$A$9:$B$18,2,FALSE)="",E15,ROUND(VLOOKUP(G15,'設定'!$A$9:$B$18,2,FALSE)*H15,2)),E15))) | N15: =IF(L15=1,COUNTIF(L$2:L15,1),"")
A16: I | B16: 2 | C16: ポーチ立上り部 | D16: 〃 | E16: 12.2 | F16: ｍ | K16: =INDEX('設定'!$G$23:$G$34,B16) | L16: =IF(K16<>1,0,IF(OR(A16="T",A16="S",A16="B"),1,IF(AND(OR(I16="",I16<='設定'!$K$2),OR(J16="",ISNUMBER(SEARCH('設定'!$K$3,J16)))),1,0))) | M16: =IF(A16<>"I","",IF(G16="",E16,IFERROR(IF(VLOOKUP(G16,'設定'!$A$9:$B$18,2,FALSE)="",E16,ROUND(VLOOKUP(G16,'設定'!$A$9:$B$18,2,FALSE)*H16,2)),E16))) | N16: =IF(L16=1,COUNTIF(L$2:L16,1),"")
A17: I | B17: 2 | C17: サッシモルタル詰め | E17: 1 | F17: 式 | K17: =INDEX('設定'!$G$23:$G$34,B17) | L17: =IF(K17<>1,0,IF(OR(A17="T",A17="S",A17="B"),1,IF(AND(OR(I17="",I17<='設定'!$K$2),OR(J17="",ISNUMBER(SEARCH('設定'!$K$3,J17)))),1,0))) | M17: =IF(A17<>"I","",IF(G17="",E17,IFERROR(IF(VLOOKUP(G17,'設定'!$A$9:$B$18,2,FALSE)="",E17,ROUND(VLOOKUP(G17,'設定'!$A$9:$B$18,2,FALSE)*H17,2)),E17))) | N17: =IF(L17=1,COUNTIF(L$2:L17,1),"")
A18: I | B18: 2 | C18: 浴室土間コンクリート | D18: 洗面室土間共 | E18: 1 | F18: 式 | K18: =INDEX('設定'!$G$23:$G$34,B18) | L18: =IF(K18<>1,0,IF(OR(A18="T",A18="S",A18="B"),1,IF(AND(OR(I18="",I18<='設定'!$K$2),OR(J18="",ISNUMBER(SEARCH('設定'!$K$3,J18)))),1,0))) | M18: =IF(A18<>"I","",IF(G18="",E18,IFERROR(IF(VLOOKUP(G18,'設定'!$A$9:$B$18,2,FALSE)="",E18,ROUND(VLOOKUP(G18,'設定'!$A$9:$B$18,2,FALSE)*H18,2)),E18))) | N18: =IF(L18=1,COUNTIF(L$2:L18,1),"")
A19: I | B19: 2 | C19: 勝手口階段 | E19: 1 | F19: 式 | K19: =INDEX('設定'!$G$23:$G$34,B19) | L19: =IF(K19<>1,0,IF(OR(A19="T",A19="S",A19="B"),1,IF(AND(OR(I19="",I19<='設定'!$K$2),OR(J19="",ISNUMBER(SEARCH('設定'!$K$3,J19)))),1,0))) | M19: =IF(A19<>"I","",IF(G19="",E19,IFERROR(IF(VLOOKUP(G19,'設定'!$A$9:$B$18,2,FALSE)="",E19,ROUND(VLOOKUP(G19,'設定'!$A$9:$B$18,2,FALSE)*H19,2)),E19))) | N19: =IF(L19=1,COUNTIF(L$2:L19,1),"")
A20: S | B20: 2 | C20: 小 計 | K20: =INDEX('設定'!$G$23:$G$34,B20) | L20: =IF(K20<>1,0,IF(OR(A20="T",A20="S",A20="B"),1,IF(AND(OR(I20="",I20<='設定'!$K$2),OR(J20="",ISNUMBER(SEARCH('設定'!$K$3,J20)))),1,0))) | M20: =IF(A20<>"I","",IF(G20="",E20,IFERROR(IF(VLOOKUP(G20,'設定'!$A$9:$B$18,2,FALSE)="",E20,ROUND(VLOOKUP(G20,'設定'!$A$9:$B$18,2,FALSE)*H20,2)),E20))) | N20: =IF(L20=1,COUNTIF(L$2:L20,1),"")
A21: B | B21: 2 | K21: =INDEX('設定'!$G$23:$G$34,B21) | L21: =IF(K21<>1,0,IF(OR(A21="T",A21="S",A21="B"),1,IF(AND(OR(I21="",I21<='設定'!$K$2),OR(J21="",ISNUMBER(SEARCH('設定'!$K$3,J21)))),1,0))) | M21: =IF(A21<>"I","",IF(G21="",E21,IFERROR(IF(VLOOKUP(G21,'設定'!$A$9:$B$18,2,FALSE)="",E21,ROUND(VLOOKUP(G21,'設定'!$A$9:$B$18,2,FALSE)*H21,2)),E21))) | N21: =IF(L21=1,COUNTIF(L$2:L21,1),"")
A22: T | B22: 3 | C22: 木工事 | K22: =INDEX('設定'!$G$23:$G$34,B22) | L22: =IF(K22<>1,0,IF(OR(A22="T",A22="S",A22="B"),1,IF(AND(OR(I22="",I22<='設定'!$K$2),OR(J22="",ISNUMBER(SEARCH('設定'!$K$3,J22)))),1,0))) | M22: =IF(A22<>"I","",IF(G22="",E22,IFERROR(IF(VLOOKUP(G22,'設定'!$A$9:$B$18,2,FALSE)="",E22,ROUND(VLOOKUP(G22,'設定'!$A$9:$B$18,2,FALSE)*H22,2)),E22))) | N22: =IF(L22=1,COUNTIF(L$2:L22,1),"")
A23: I | B23: 3 | C23: 材木費 | E23: 37 | F23: 坪 | G23: tsubo | H23: 1 | J23: wood | K23: =INDEX('設定'!$G$23:$G$34,B23) | L23: =IF(K23<>1,0,IF(OR(A23="T",A23="S",A23="B"),1,IF(AND(OR(I23="",I23<='設定'!$K$2),OR(J23="",ISNUMBER(SEARCH('設定'!$K$3,J23)))),1,0))) | M23: =IF(A23<>"I","",IF(G23="",E23,IFERROR(IF(VLOOKUP(G23,'設定'!$A$9:$B$18,2,FALSE)="",E23,ROUND(VLOOKUP(G23,'設定'!$A$9:$B$18,2,FALSE)*H23,2)),E23))) | N23: =IF(L23=1,COUNTIF(L$2:L23,1),"")
A24: I | B24: 3 | C24: 木造作費 | E24: 37 | F24: 坪 | G24: tsubo | H24: 1 | J24: wood | K24: =INDEX('設定'!$G$23:$G$34,B24) | L24: =IF(K24<>1,0,IF(OR(A24="T",A24="S",A24="B"),1,IF(AND(OR(I24="",I24<='設定'!$K$2),OR(J24="",ISNUMBER(SEARCH('設定'!$K$3,J24)))),1,0))) | M24: =IF(A24<>"I","",IF(G24="",E24,IFERROR(IF(VLOOKUP(G24,'設定'!$A$9:$B$18,2,FALSE)="",E24,ROUND(VLOOKUP(G24,'設定'!$A$9:$B$18,2,FALSE)*H24,2)),E24))) | N24: =IF(L24=1,COUNTIF(L$2:L24,1),"")
A25: I | B25: 3 | C25: 金物費 | E25: 37 | F25: 坪 | G25: tsubo | H25: 1 | J25: wood | K25: =INDEX('設定'!$G$23:$G$34,B25) | L25: =IF(K25<>1,0,IF(OR(A25="T",A25="S",A25="B"),1,IF(AND(OR(I25="",I25<='設定'!$K$2),OR(J25="",ISNUMBER(SEARCH('設定'!$K$3,J25)))),1,0))) | M25: =IF(A25<>"I","",IF(G25="",E25,IFERROR(IF(VLOOKUP(G25,'設定'!$A$9:$B$18,2,FALSE)="",E25,ROUND(VLOOKUP(G25,'設定'!$A$9:$B$18,2,FALSE)*H25,2)),E25))) | N25: =IF(L25=1,COUNTIF(L$2:L25,1),"")
A26: I | B26: 3 | C26: 防蟻処理 | D26: ホウ酸散布 | E26: 122 | F26: ㎡ | G26: total_area | H26: 1 | J26: wood | K26: =INDEX('設定'!$G$23:$G$34,B26) | L26: =IF(K26<>1,0,IF(OR(A26="T",A26="S",A26="B"),1,IF(AND(OR(I26="",I26<='設定'!$K$2),OR(J26="",ISNUMBER(SEARCH('設定'!$K$3,J26)))),1,0))) | M26: =IF(A26<>"I","",IF(G26="",E26,IFERROR(IF(VLOOKUP(G26,'設定'!$A$9:$B$18,2,FALSE)="",E26,ROUND(VLOOKUP(G26,'設定'!$A$9:$B$18,2,FALSE)*H26,2)),E26))) | N26: =IF(L26=1,COUNTIF(L$2:L26,1),"")
A27: I | B27: 3 | C27: 軽量鉄骨下地（壁・天井） | E27: 1 | F27: ㎡ | G27: total_area | H27: 1 | J27: steel,rc | K27: =INDEX('設定'!$G$23:$G$34,B27) | L27: =IF(K27<>1,0,IF(OR(A27="T",A27="S",A27="B"),1,IF(AND(OR(I27="",I27<='設定'!$K$2),OR(J27="",ISNUMBER(SEARCH('設定'!$K$3,J27)))),1,0))) | M27: =IF(A27<>"I","",IF(G27="",E27,IFERROR(IF(VLOOKUP(G27,'設定'!$A$9:$B$18,2,FALSE)="",E27,ROUND(VLOOKUP(G27,'設定'!$A$9:$B$18,2,FALSE)*H27,2)),E27))) | N27: =IF(L27=1,COUNTIF(L$2:L27,1),"")
A28: S | B28: 3 | C28: 小 計 | K28: =INDEX('設定'!$G$23:$G$34,B28) | L28: =IF(K28<>1,0,IF(OR(A28="T",A28="S",A28="B"),1,IF(AND(OR(I28="",I28<='設定'!$K$2),OR(J28="",ISNUMBER(SEARCH('設定'!$K$3,J28)))),1,0))) | M28: =IF(A28<>"I","",IF(G28="",E28,IFERROR(IF(VLOOKUP(G28,'設定'!$A$9:$B$18,2,FALSE)="",E28,ROUND(VLOOKUP(G28,'設定'!$A$9:$B$18,2,FALSE)*H28,2)),E28))) | N28: =IF(L28=1,COUNTIF(L$2:L28,1),"")
A29: B | B29: 3 | K29: =INDEX('設定'!$G$23:$G$34,B29) | L29: =IF(K29<>1,0,IF(OR(A29="T",A29="S",A29="B"),1,IF(AND(OR(I29="",I29<='設定'!$K$2),OR(J29="",ISNUMBER(SEARCH('設定'!$K$3,J29)))),1,0))) | M29: =IF(A29<>"I","",IF(G29="",E29,IFERROR(IF(VLOOKUP(G29,'設定'!$A$9:$B$18,2,FALSE)="",E29,ROUND(VLOOKUP(G29,'設定'!$A$9:$B$18,2,FALSE)*H29,2)),E29))) | N29: =IF(L29=1,COUNTIF(L$2:L29,1),"")
A30: T | B30: 4 | C30: 屋根板金工事 | K30: =INDEX('設定'!$G$23:$G$34,B30) | L30: =IF(K30<>1,0,IF(OR(A30="T",A30="S",A30="B"),1,IF(AND(OR(I30="",I30<='設定'!$K$2),OR(J30="",ISNUMBER(SEARCH('設定'!$K$3,J30)))),1,0))) | M30: =IF(A30<>"I","",IF(G30="",E30,IFERROR(IF(VLOOKUP(G30,'設定'!$A$9:$B$18,2,FALSE)="",E30,ROUND(VLOOKUP(G30,'設定'!$A$9:$B$18,2,FALSE)*H30,2)),E30))) | N30: =IF(L30=1,COUNTIF(L$2:L30,1),"")
A31: G | B31: 4 | C31: 【屋根】 | K31: =INDEX('設定'!$G$23:$G$34,B31) | L31: =IF(K31<>1,0,IF(OR(A31="T",A31="S",A31="B"),1,IF(AND(OR(I31="",I31<='設定'!$K$2),OR(J31="",ISNUMBER(SEARCH('設定'!$K$3,J31)))),1,0))) | M31: =IF(A31<>"I","",IF(G31="",E31,IFERROR(IF(VLOOKUP(G31,'設定'!$A$9:$B$18,2,FALSE)="",E31,ROUND(VLOOKUP(G31,'設定'!$A$9:$B$18,2,FALSE)*H31,2)),E31))) | N31: =IF(L31=1,COUNTIF(L$2:L31,1),"")
A32: I | B32: 4 | C32: 屋根GL立平葺き | E32: 83 | F32: ㎡ | G32: roof_area | H32: 1 | K32: =INDEX('設定'!$G$23:$G$34,B32) | L32: =IF(K32<>1,0,IF(OR(A32="T",A32="S",A32="B"),1,IF(AND(OR(I32="",I32<='設定'!$K$2),OR(J32="",ISNUMBER(SEARCH('設定'!$K$3,J32)))),1,0))) | M32: =IF(A32<>"I","",IF(G32="",E32,IFERROR(IF(VLOOKUP(G32,'設定'!$A$9:$B$18,2,FALSE)="",E32,ROUND(VLOOKUP(G32,'設定'!$A$9:$B$18,2,FALSE)*H32,2)),E32))) | N32: =IF(L32=1,COUNTIF(L$2:L32,1),"")
A33: I | B33: 4 | C33: 屋根ｶﾗｸｻ | E33: 47 | F33: ⅿ | K33: =INDEX('設定'!$G$23:$G$34,B33) | L33: =IF(K33<>1,0,IF(OR(A33="T",A33="S",A33="B"),1,IF(AND(OR(I33="",I33<='設定'!$K$2),OR(J33="",ISNUMBER(SEARCH('設定'!$K$3,J33)))),1,0))) | M33: =IF(A33<>"I","",IF(G33="",E33,IFERROR(IF(VLOOKUP(G33,'設定'!$A$9:$B$18,2,FALSE)="",E33,ROUND(VLOOKUP(G33,'設定'!$A$9:$B$18,2,FALSE)*H33,2)),E33))) | N33: =IF(L33=1,COUNTIF(L$2:L33,1),"")
A34: I | B34: 4 | C34: ｺﾞﾑｱｽﾙｰﾌｨﾝｸﾞ | E34: 83 | F34: ㎡ | G34: roof_area | H34: 1 | K34: =INDEX('設定'!$G$23:$G$34,B34) | L34: =IF(K34<>1,0,IF(OR(A34="T",A34="S",A34="B"),1,IF(AND(OR(I34="",I34<='設定'!$K$2),OR(J34="",ISNUMBER(SEARCH('設定'!$K$3,J34)))),1,0))) | M34: =IF(A34<>"I","",IF(G34="",E34,IFERROR(IF(VLOOKUP(G34,'設定'!$A$9:$B$18,2,FALSE)="",E34,ROUND(VLOOKUP(G34,'設定'!$A$9:$B$18,2,FALSE)*H34,2)),E34))) | N34: =IF(L34=1,COUNTIF(L$2:L34,1),"")
A35: I | B35: 4 | C35: 雪止め1段 | E35: 78 | F35: ヶ | K35: =INDEX('設定'!$G$23:$G$34,B35) | L35: =IF(K35<>1,0,IF(OR(A35="T",A35="S",A35="B"),1,IF(AND(OR(I35="",I35<='設定'!$K$2),OR(J35="",ISNUMBER(SEARCH('設定'!$K$3,J35)))),1,0))) | M35: =IF(A35<>"I","",IF(G35="",E35,IFERROR(IF(VLOOKUP(G35,'設定'!$A$9:$B$18,2,FALSE)="",E35,ROUND(VLOOKUP(G35,'設定'!$A$9:$B$18,2,FALSE)*H35,2)),E35))) | N35: =IF(L35=1,COUNTIF(L$2:L35,1),"")
A36: I | B36: 4 | C36: 立上水切 | E36: 20 | F36: ⅿ | K36: =INDEX('設定'!$G$23:$G$34,B36) | L36: =IF(K36<>1,0,IF(OR(A36="T",A36="S",A36="B"),1,IF(AND(OR(I36="",I36<='設定'!$K$2),OR(J36="",ISNUMBER(SEARCH('設定'!$K$3,J36)))),1,0))) | M36: =IF(A36<>"I","",IF(G36="",E36,IFERROR(IF(VLOOKUP(G36,'設定'!$A$9:$B$18,2,FALSE)="",E36,ROUND(VLOOKUP(G36,'設定'!$A$9:$B$18,2,FALSE)*H36,2)),E36))) | N36: =IF(L36=1,COUNTIF(L$2:L36,1),"")
A37: I | B37: 4 | C37: 棟板金 | E37: 11.5 | F37: ⅿ | K37: =INDEX('設定'!$G$23:$G$34,B37) | L37: =IF(K37<>1,0,IF(OR(A37="T",A37="S",A37="B"),1,IF(AND(OR(I37="",I37<='設定'!$K$2),OR(J37="",ISNUMBER(SEARCH('設定'!$K$3,J37)))),1,0))) | M37: =IF(A37<>"I","",IF(G37="",E37,IFERROR(IF(VLOOKUP(G37,'設定'!$A$9:$B$18,2,FALSE)="",E37,ROUND(VLOOKUP(G37,'設定'!$A$9:$B$18,2,FALSE)*H37,2)),E37))) | N37: =IF(L37=1,COUNTIF(L$2:L37,1),"")
A38: I | B38: 4 | C38: 谷板工事 | E38: 1.7 | F38: ⅿ | K38: =INDEX('設定'!$G$23:$G$34,B38) | L38: =IF(K38<>1,0,IF(OR(A38="T",A38="S",A38="B"),1,IF(AND(OR(I38="",I38<='設定'!$K$2),OR(J38="",ISNUMBER(SEARCH('設定'!$K$3,J38)))),1,0))) | M38: =IF(A38<>"I","",IF(G38="",E38,IFERROR(IF(VLOOKUP(G38,'設定'!$A$9:$B$18,2,FALSE)="",E38,ROUND(VLOOKUP(G38,'設定'!$A$9:$B$18,2,FALSE)*H38,2)),E38))) | N38: =IF(L38=1,COUNTIF(L$2:L38,1),"")
A39: I | B39: 4 | C39: 荷上げﾚｯｶｰ代 | E39: 1 | F39: 式 | K39: =INDEX('設定'!$G$23:$G$34,B39) | L39: =IF(K39<>1,0,IF(OR(A39="T",A39="S",A39="B"),1,IF(AND(OR(I39="",I39<='設定'!$K$2),OR(J39="",ISNUMBER(SEARCH('設定'!$K$3,J39)))),1,0))) | M39: =IF(A39<>"I","",IF(G39="",E39,IFERROR(IF(VLOOKUP(G39,'設定'!$A$9:$B$18,2,FALSE)="",E39,ROUND(VLOOKUP(G39,'設定'!$A$9:$B$18,2,FALSE)*H39,2)),E39))) | N39: =IF(L39=1,COUNTIF(L$2:L39,1),"")
A40: G | B40: 4 | C40: 【外壁】 | K40: =INDEX('設定'!$G$23:$G$34,B40) | L40: =IF(K40<>1,0,IF(OR(A40="T",A40="S",A40="B"),1,IF(AND(OR(I40="",I40<='設定'!$K$2),OR(J40="",ISNUMBER(SEARCH('設定'!$K$3,J40)))),1,0))) | M40: =IF(A40<>"I","",IF(G40="",E40,IFERROR(IF(VLOOKUP(G40,'設定'!$A$9:$B$18,2,FALSE)="",E40,ROUND(VLOOKUP(G40,'設定'!$A$9:$B$18,2,FALSE)*H40,2)),E40))) | N40: =IF(L40=1,COUNTIF(L$2:L40,1),"")
...

Sheet 設定
A1: 構造 | B1: キー | D1: 階数 | E1: 数値 | G1: 工事タイプ | J1: 自動計算 | K1: 値
A2: 木造 | B2: wood | D2: 平屋 | E2: 1 | G2: フルリノベーション | J2: 階数(数値) | K2: =MATCH('入力'!B17,$D$2:$D$4,0)
A3: 鉄骨造 | B3: steel | D3: 2階建て | E3: 2 | G3: 水回りリフォーム | J3: 構造キー | K3: =INDEX($B$2:$B$4,MATCH('入力'!B16,$A$2:$A$4,0))
A4: RC造 | B4: rc | D4: 3階建て | E4: 3 | G4: 内装リフォーム | J4: 延床面積(㎡) | K4: =IF(AND('入力'!B21="",IF(K2>=2,'入力'!B22,"")="",IF(K2>=3,'入力'!B23,"")=""),"",N('入力'!B21)+IF(K2>=2,N('入力'!B22),0)+IF(K2>=3,N('入力'!B23),0))
G5: 外装リフォーム | J5: 延床面積(坪) | K5: =IF(K4="","",ROUND(K4/3.30579,2))
J6: 足場面積 | K6: =IF('入力'!B26<>"",'入力'!B26,IF('入力'!B25<>"",'入力'!B25,""))
J7: 工事タイプ番号 | K7: =MATCH('入力'!B18,$G$2:$G$5,0)
A8: 基準キー | B8: 値（入力シートから自動）
A9: floor1_area | B9: =IF('入力'!B21="","",'入力'!B21)
A10: floor2_area | B10: =IF(AND(K2>=2,'入力'!B22<>""),'入力'!B22,"")
A11: floor3_area | B11: =IF(AND(K2>=3,'入力'!B23<>""),'入力'!B23,"")
A12: total_area | B12: =K4
A13: tsubo | B13: =K5
A14: roof_area | B14: =IF('入力'!B24="","",'入力'!B24)
A15: wall_area | B15: =IF('入力'!B25="","",'入力'!B25)
A16: scaffold_area | B16: =K6
A17: toilet_count | B17: =IF('入力'!B27="","",'入力'!B27)
A18: cloth_len | B18: =IF('入力'!B28="","",'入力'!B28)
A22: 工事ID | B22: 工事名 | C22: フルリノベーション | D22: 水回りリフォーム | E22: 内装リフォーム | F22: 外装リフォーム | G22: 採用 | H22: 採用連番
A23: 1 | B23: 解体工事 | C23: 1 | D23: 1 | E23: 1 | F23: 0 | G23: =IF('入力'!C33="○",1,IF('入力'!C33="×",0,IF(INDEX(C23:F23,$K$7)=1,1,0))) | H23: =IF(G23=1,COUNTIF(G$23:G23,1),"")
A24: 2 | B24: 基礎工事 | C24: 1 | D24: 0 | E24: 0 | F24: 0 | G24: =IF('入力'!C34="○",1,IF('入力'!C34="×",0,IF(INDEX(C24:F24,$K$7)=1,1,0))) | H24: =IF(G24=1,COUNTIF(G$23:G24,1),"")
A25: 3 | B25: 木工事 | C25: 1 | D25: 0 | E25: 1 | F25: 0 | G25: =IF('入力'!C35="○",1,IF('入力'!C35="×",0,IF(INDEX(C25:F25,$K$7)=1,1,0))) | H25: =IF(G25=1,COUNTIF(G$23:G25,1),"")
A26: 4 | B26: 屋根板金工事 | C26: 1 | D26: 0 | E26: 0 | F26: 1 | G26: =IF('入力'!C36="○",1,IF('入力'!C36="×",0,IF(INDEX(C26:F26,$K$7)=1,1,0))) | H26: =IF(G26=1,COUNTIF(G$23:G26,1),"")
A27: 5 | B27: 内外装工事 | C27: 1 | D27: 0 | E27: 1 | F27: 1 | G27: =IF('入力'!C37="○",1,IF('入力'!C37="×",0,IF(INDEX(C27:F27,$K$7)=1,1,0))) | H27: =IF(G27=1,COUNTIF(G$23:G27,1),"")
A28: 6 | B28: 鋼製建具工事 | C28: 1 | D28: 0 | E28: 0 | F28: 0 | G28: =IF('入力'!C38="○",1,IF('入力'!C38="×",0,IF(INDEX(C28:F28,$K$7)=1,1,0))) | H28: =IF(G28=1,COUNTIF(G$23:G28,1),"")
A29: 7 | B29: 塗装工事 | C29: 1 | D29: 0 | E29: 1 | F29: 1 | G29: =IF('入力'!C39="○",1,IF('入力'!C39="×",0,IF(INDEX(C29:F29,$K$7)=1,1,0))) | H29: =IF(G29=1,COUNTIF(G$23:G29,1),"")
A30: 8 | B30: 電気設備工事 | C30: 1 | D30: 1 | E30: 1 | F30: 0 | G30: =IF('入力'!C40="○",1,IF('入力'!C40="×",0,IF(INDEX(C30:F30,$K$7)=1,1,0))) | H30: =IF(G30=1,COUNTIF(G$23:G30,1),"")
A31: 9 | B31: 給排水設備工事 | C31: 1 | D31: 1 | E31: 0 | F31: 0 | G31: =IF('入力'!C41="○",1,IF('入力'!C41="×",0,IF(INDEX(C31:F31,$K$7)=1,1,0))) | H31: =IF(G31=1,COUNTIF(G$23:G31,1),"")
A32: 10 | B32: 住宅設備工事 | C32: 1 | D32: 1 | E32: 0 | F32: 0 | G32: =IF('入力'!C42="○",1,IF('入力'!C42="×",0,IF(INDEX(C32:F32,$K$7)=1,1,0))) | H32: =IF(G32=1,COUNTIF(G$23:G32,1),"")
A33: 11 | B33: 仮設工事 | C33: 1 | D33: 1 | E33: 1 | F33: 1 | G33: =IF('入力'!C43="○",1,IF('入力'!C43="×",0,IF(INDEX(C33:F33,$K$7)=1,1,0))) | H33: =IF(G33=1,COUNTIF(G$23:G33,1),"")
A34: 12 | B34: 諸経費 | C34: 1 | D34: 1 | E34: 1 | F34: 1 | G34: =IF('入力'!C44="○",1,IF('入力'!C44="×",0,IF(INDEX(C34:F34,$K$7)=1,1,0))) | H34: =IF(G34=1,COUNTIF(G$23:G34,1),"")
